Workbook

Sheet Commencer
B2: ORNELLA FIT COACHING
B3: Planner Ventre & Fessiers — 8 semaines
B4: Ton programme, tes calories et ton suivi, au même endroit.
B7: Comment l'utiliser (5 min)
B8: 1. Onglet « Mes calories » : remplis tes infos → tes calories et macros se calculent toutes seules.
B9: 2. Indique ta date de début : tout ton planning se date automatiquement.
B10: 3. Onglet « Programme 8 sem » : chaque jour, coche ✓ ta séance et tes habitudes (eau, pas, protéines, sommeil).
B11: 4. Onglet « Séances » : le détail de chaque entraînement, avec la progression phase par phase.
B12: 5. Onglet « Mon suivi » : 1 fois par semaine, même jour, même heure → poids + mensurations. Les graphiques bougent tout seuls.
B13: 6. Onglet « Repas » : compose ta journée type et vois si tu es dans ton objectif calories.
B14: 📱 Sur téléphone : installe l'appli Google Sheets, c'est plus confortable pour cocher tes cases.
B16: Légende
C17: Case corail clair = à remplir par toi
B18: ✓ | C18: Menu déroulant : choisis ✓ quand c'est fait
C19: Les cases blanches se calculent toutes seules (ne pas effacer)
B21: Ta semaine type
B22: Jour 1 | C22: A — Fessiers & Jambes
B23: Jour 2 | C23: B — Ventre & Gainage
B24: Jour 3 | C24: Marche active 30-45 min
B25: Jour 4 | C25: C — Full body brûle-calories
B26: Jour 5 | C26: D — Fessiers Sculpt
B27: Jour 6 | C27: Marche + mobilité
B28: Jour 7 | C28: Repos
B30: Important
B31: Ce planner est un outil d'organisation et de motivation, pas un avis médical. Les calories sont des estimations. Si tu es enceinte, en post-partum récent (ou diastasis), si tu as une pathologie, une blessure ou un historique de troubles alimentaires, demande l'avis d'un professionnel de santé avant de commencer. Écoute ton corps : douleur = stop.
B33: Créé par Ornella — coach sportive diplômée d'État (BPJEPS) · ornellafitcoaching.com

Sheet Mes calories
B2: ORNELLA FIT COACHING
B3: Mes calories & macros
B4: Remplis les cases corail. Tout le reste se calcule.
B7: 1 · Mes infos
B8: Prénom | C8: Julie
B9: Date de début | C9: 46300 | E9: Mets la date de ton Jour 1 (ex : lundi prochain).
B10: Âge (ans) | C10: 34
B11: Poids (kg) | C11: 72 | D11: kg
B12: Taille (cm) | C12: 165 | D12: cm
B13: Niveau d'activité | C13: Légèrement active (1-3 séances/sem) | E13: Choisis dans la liste ▾
B14: Objectif | C14: Perte régulière (-15 %) | E14: Choisis dans la liste ▾
B16: 2 · Mes résultats
B17: Métabolisme de base | C17: =IF(AND(C10<>"",C11<>"",C12<>"",C13<>"",C14<>""),ROUND((10*Listes!$H$3+6.25*Listes!$I$3-5*C10-161),0),"") -> 1420 | D17: kcal | E17: Calories brûlées au repos (formule Mifflin-St Jeor).
B18: Dépense journalière estimée | C18: =IF(AND(C10<>"",C11<>"",C12<>"",C13<>"",C14<>""),ROUND(C17*INDEX(Listes!$C$3:$C$6,MATCH(C13,Listes!$B$3:$B$6,0)),0),"") -> 1953 | D18: kcal | E18: Métabolisme × niveau d'activité.
B19: 🎯 Mon objectif calories / jour | C19: =IF(AND(C10<>"",C11<>"",C12<>"",C13<>"",C14<>""),ROUND(MAX(C18*(1-INDEX(Listes!$F$3:$F$6,MATCH(C14,Listes!$E$3:$E$6,0))),C17),-1),"") -> 1660 | D19: kcal | E19: Jamais en dessous de ton métabolisme de base : on perd du gras, pas de l'énergie.
B20: Protéines / jour | C20: =IF(AND(C10<>"",C11<>"",C12<>"",C13<>"",C14<>""),ROUND(1.8*Listes!$H$3,0),"") -> 130 | D20: g | E20: 1,8 g par kg : protège tes muscles et coupe la faim.
B21: Lipides / jour | C21: =IF(AND(C10<>"",C11<>"",C12<>"",C13<>"",C14<>""),ROUND(C19*0.28/9,0),"") -> 52 | D21: g | E21: ≈ 28 % des calories : indispensable pour tes hormones.
B22: Glucides / jour | C22: =IF(AND(C10<>"",C11<>"",C12<>"",C13<>"",C14<>""),ROUND(MAX(C19-C20*4-C21*9,0)/4,0),"") -> 168 | D22: g | E22: Le reste des calories : ton carburant pour les séances.
B23: Eau / jour | C23: =IF(AND(C10<>"",C11<>"",C12<>"",C13<>"",C14<>""),ROUND(Listes!$H$3*0.035,1),"") -> 2.5 | D23: L | E23: ≈ 35 ml par kg de poids.
B24: Pas / jour | C24: 8000 | D24: pas | E24: Objectif simple et efficace au quotidien.
B26: 💡 Astuce : ne change pas tes calories avant 2 semaines. Si ton tour de taille ne bouge pas après 3 semaines, passe à l'objectif suivant.

Sheet Programme 8 sem
B2: ORNELLA FIT COACHING
B3: Programme 8 semaines + suivi quotidien
B4: Chaque jour : choisis ✓ dans les cases de ce que tu as fait.
B7: Séances faites | F7: Progression programme | J7: Habitudes validées
B8: =COUNTIF(H11:H66,"✓")&" / "&COUNTIF(N11:N66,1) -> 0 / 48 | F8: =IF(COUNTIF(N11:N66,1)=0,0,COUNTIF(H11:H66,"✓")/COUNTIF(N11:N66,1)) -> 0 | J8: =COUNTIF(I11:L66,"✓")/(56*4) -> 0
B10: Sem. | C10: Phase | D10: Jour | E10: Date | F10: Séance du jour | G10: Durée | H10: ✓ Séance | I10: 💧 Eau | J10: 👟 Pas | K10: 🍗 Protéines | L10: 😴 Sommeil 7h | M10: Score | N10: planned
B11: 1 | C11: Fondation | D11: J1 | E11: =IF('Mes calories'!$C$9="","",'Mes calories'!$C$9+0) -> 46300 | F11: A — Fessiers & Jambes | G11: 35 min | M11: =COUNTIF(H11:L11,"✓")&"/"&5 -> 0/5 | N11: 1
B12: 1 | C12: Fondation | D12: J2 | E12: =IF('Mes calories'!$C$9="","",'Mes calories'!$C$9+1) -> 46301 | F12: B — Ventre & Gainage | G12: 25 min | M12: =COUNTIF(H12:L12,"✓")&"/"&5 -> 0/5 | N12: 1
B13: 1 | C13: Fondation | D13: J3 | E13: =IF('Mes calories'!$C$9="","",'Mes calories'!$C$9+2) -> 46302 | F13: Marche active | G13: 30-45 min | M13: =COUNTIF(H13:L13,"✓")&"/"&5 -> 0/5 | N13: 1
B14: 1 | C14: Fondation | D14: J4 | E14: =IF('Mes calories'!$C$9="","",'Mes calories'!$C$9+3) -> 46303 | F14: C — Full body brûle-calories | G14: 30 min | M14: =COUNTIF(H14:L14,"✓")&"/"&5 -> 0/5 | N14: 1
B15: 1 | C15: Fondation | D15: J5 | E15: =IF('Mes calories'!$C$9="","",'Mes calories'!$C$9+4) -> 46304 | F15: D — Fessiers Sculpt | G15: 35 min | M15: =COUNTIF(H15:L15,"✓")&"/"&5 -> 0/5 | N15: 1
B16: 1 | C16: Fondation | D16: J6 | E16: =IF('Mes calories'!$C$9="","",'Mes calories'!$C$9+5) -> 46305 | F16: Marche + mobilité | G16: 30 min | M16: =COUNTIF(H16:L16,"✓")&"/"&5 -> 0/5 | N16: 1
B17: 1 | C17: Fondation | D17: J7 | E17: =IF('Mes calories'!$C$9="","",'Mes calories'!$C$9+6) -> 46306 | F17: Repos | G17: — | H17: — | M17: =COUNTIF(H17:L17,"✓")&"/"&4 -> 0/4 | N17: 0
B18: 2 | C18: Fondation | D18: J1 | E18: =IF('Mes calories'!$C$9="","",'Mes calories'!$C$9+7) -> 46307 | F18: A — Fessiers & Jambes | G18: 35 min | M18: =COUNTIF(H18:L18,"✓")&"/"&5 -> 0/5 | N18: 1
B19: 2 | C19: Fondation | D19: J2 | E19: =IF('Mes calories'!$C$9="","",'Mes calories'!$C$9+8) -> 46308 | F19: B — Ventre & Gainage | G19: 25 min | M19: =COUNTIF(H19:L19,"✓")&"/"&5 -> 0/5 | N19: 1
B20: 2 | C20: Fondation | D20: J3 | E20: =IF('Mes calories'!$C$9="","",'Mes calories'!$C$9+9) -> 46309 | F20: Marche active | G20: 30-45 min | M20: =COUNTIF(H20:L20,"✓")&"/"&5 -> 0/5 | N20: 1
B21: 2 | C21: Fondation | D21: J4 | E21: =IF('Mes calories'!$C$9="","",'Mes calories'!$C$9+10) -> 46310 | F21: C — Full body brûle-calories | G21: 30 min | M21: =COUNTIF(H21:L21,"✓")&"/"&5 -> 0/5 | N21: 1
B22: 2 | C22: Fondation | D22: J5 | E22: =IF('Mes calories'!$C$9="","",'Mes calories'!$C$9+11) -> 46311 | F22: D — Fessiers Sculpt | G22: 35 min | M22: =COUNTIF(H22:L22,"✓")&"/"&5 -> 0/5 | N22: 1
B23: 2 | C23: Fondation | D23: J6 | E23: =IF('Mes calories'!$C$9="","",'Mes calories'!$C$9+12) -> 46312 | F23: Marche + mobilité | G23: 30 min | M23: =COUNTIF(H23:L23,"✓")&"/"&5 -> 0/5 | N23: 1
B24: 2 | C24: Fondation | D24: J7 | E24: =IF('Mes calories'!$C$9="","",'Mes calories'!$C$9+13) -> 46313 | F24: Repos | G24: — | H24: — | M24: =COUNTIF(H24:L24,"✓")&"/"&4 -> 0/4 | N24: 0
B25: 3 | C25: Progression | D25: J1 | E25: =IF('Mes calories'!$C$9="","",'Mes calories'!$C$9+14) -> 46314 | F25: A — Fessiers & Jambes | G25: 35 min | M25: =COUNTIF(H25:L25,"✓")&"/"&5 -> 0/5 | N25: 1
B26: 3 | C26: Progression | D26: J2 | E26: =IF('Mes calories'!$C$9="","",'Mes calories'!$C$9+15) -> 46315 | F26: B — Ventre & Gainage | G26: 25 min | M26: =COUNTIF(H26:L26,"✓")&"/"&5 -> 0/5 | N26: 1
B27: 3 | C27: Progression | D27: J3 | E27: =IF('Mes calories'!$C$9="","",'Mes calories'!$C$9+16) -> 46316 | F27: Marche active | G27: 30-45 min | M27: =COUNTIF(H27:L27,"✓")&"/"&5 -> 0/5 | N27: 1
B28: 3 | C28: Progression | D28: J4 | E28: =IF('Mes calories'!$C$9="","",'Mes calories'!$C$9+17) -> 46317 | F28: C — Full body brûle-calories | G28: 30 min | M28: =COUNTIF(H28:L28,"✓")&"/"&5 -> 0/5 | N28: 1
B29: 3 | C29: Progression | D29: J5 | E29: =IF('Mes calories'!$C$9="","",'Mes calories'!$C$9+18) -> 46318 | F29: D — Fessiers Sculpt | G29: 35 min | M29: =COUNTIF(H29:L29,"✓")&"/"&5 -> 0/5 | N29: 1
B30: 3 | C30: Progression | D30: J6 | E30: =IF('Mes calories'!$C$9="","",'Mes calories'!$C$9+19) -> 46319 | F30: Marche + mobilité | G30: 30 min | M30: =COUNTIF(H30:L30,"✓")&"/"&5 -> 0/5 | N30: 1
B31: 3 | C31: Progression | D31: J7 | E31: =IF('Mes calories'!$C$9="","",'Mes calories'!$C$9+20) -> 46320 | F31: Repos | G31: — | H31: — | M31: =COUNTIF(H31:L31,"✓")&"/"&4 -> 0/4 | N31: 0
B32: 4 | C32: Progression | D32: J1 | E32: =IF('Mes calories'!$C$9="","",'Mes calories'!$C$9+21) -> 46321 | F32: A — Fessiers & Jambes | G32: 35 min | M32: =COUNTIF(H32:L32,"✓")&"/"&5 -> 0/5 | N32: 1
B33: 4 | C33: Progression | D33: J2 | E33: =IF('Mes calories'!$C$9="","",'Mes calories'!$C$9+22) -> 46322 | F33: B — Ventre & Gainage | G33: 25 min | M33: =COUNTIF(H33:L33,"✓")&"/"&5 -> 0/5 | N33: 1
B34: 4 | C34: Progression | D34: J3 | E34: =IF('Mes calories'!$C$9="","",'Mes calories'!$C$9+23) -> 46323 | F34: Marche active | G34: 30-45 min | M34: =COUNTIF(H34:L34,"✓")&"/"&5 -> 0/5 | N34: 1
B35: 4 | C35: Progression | D35: J4 | E35: =IF('Mes calories'!$C$9="","",'Mes calories'!$C$9+24) -> 46324 | F35: C — Full body brûle-calories | G35: 30 min | M35: =COUNTIF(H35:L35,"✓")&"/"&5 -> 0/5 | N35: 1
B36: 4 | C36: Progression | D36: J5 | E36: =IF('Mes calories'!$C$9="","",'Mes calories'!$C$9+25) -> 46325 | F36: D — Fessiers Sculpt | G36: 35 min | M36: =COUNTIF(H36:L36,"✓")&"/"&5 -> 0/5 | N36: 1
B37: 4 | C37: Progression | D37: J6 | E37: =IF('Mes calories'!$C$9="","",'Mes calories'!$C$9+26) -> 46326 | F37: Marche + mobilité | G37: 30 min | M37: =COUNTIF(H37:L37,"✓")&"/"&5 -> 0/5 | N37: 1
B38: 4 | C38: Progression | D38: J7 | E38: =IF('Mes calories'!$C$9="","",'Mes calories'!$C$9+27) -> 46327 | F38: Repos | G38: — | H38: — | M38: =COUNTIF(H38:L38,"✓")&"/"&4 -> 0/4 | N38: 0
B39: 5 | C39: Progression | D39: J1 | E39: =IF('Mes calories'!$C$9="","",'Mes calories'!$C$9+28) -> 46328 | F39: A — Fessiers & Jambes | G39: 35 min | M39: =COUNTIF(H39:L39,"✓")&"/"&5 -> 0/5 | N39: 1
B40: 5 | C40: Progression | D40: J2 | E40: =IF('Mes calories'!$C$9="","",'Mes calories'!$C$9+29) -> 46329 | F40: B — Ventre & Gainage | G40: 25 min | M40: =COUNTIF(H40:L40,"✓")&"/"&5 -> 0/5 | N40: 1
B41: 5 | C41: Progression | D41: J3 | E41: =IF('Mes calories'!$C$9="","",'Mes calories'!$C$9+30) -> 46330 | F41: Marche active | G41: 30-45 min | M41: =COUNTIF(H41:L41,"✓")&"/"&5 -> 0/5 | N41: 1
B42: 5 | C42: Progression | D42: J4 | E42: =IF('Mes calories'!$C$9="","",'Mes calories'!$C$9+31) -> 46331 | F42: C — Full body brûle-calories | G42: 30 min | M42: =COUNTIF(H42:L42,"✓")&"/"&5 -> 0/5 | N42: 1
B43: 5 | C43: Progression | D43: J5 | E43: =IF('Mes calories'!$C$9="","",'Mes calories'!$C$9+32) -> 46332 | F43: D — Fessiers Sculpt | G43: 35 min | M43: =COUNTIF(H43:L43,"✓")&"/"&5 -> 0/5 | N43: 1
B44: 5 | C44: Progression | D44: J6 | E44: =IF('Mes calories'!$C$9="","",'Mes calories'!$C$9+33) -> 46333 | F44: Marche + mobilité | G44: 30 min | M44: =COUNTIF(H44:L44,"✓")&"/"&5 -> 0/5 | N44: 1
...

Sheet Séances
B2: ORNELLA FIT COACHING
B3: Détail des séances
B4: Phase 1 = semaines 1-2 · Phase 2 = semaines 3-5 · Phase 3 = semaines 6-8
B7: Échauffement — 5 min (avant chaque séance)
B8: 2 tours, 30 s chacun : rotations de bras · montées de genoux · squats lents · fentes avec rotation · ponts fessiers · gainage sur les genoux
B10: A — Fessiers & Jambes · 35 min
B11: Exercice | C11: Phase 1 (S1-2) | D11: Phase 2 (S3-5) | E11: Phase 3 (S6-8) | F11: Le conseil d'Ornella
B12: Pont fessier au sol | C12: 3 × 15 | D12: 4 × 15 (pause 2 s en haut) | E12: 4 × 12 sur 1 jambe / côté | F12: Pousse dans les talons, serre fort les fessiers en haut.
B13: Squat sumo | C13: 3 × 12 | D13: 4 × 12 (descente en 3 s) | E13: 4 × 15 + 10 pulses | F13: Pieds larges, pointes vers l'extérieur, genoux dans l'axe.
B14: Fentes arrière | C14: 3 × 10 / jambe | D14: 4 × 10 / jambe | E14: 4 × 12 / jambe (avec charge) | F14: Buste légèrement penché = plus de fessiers.
B15: Abduction couchée sur le côté | C15: 3 × 15 / côté | D15: 3 × 20 / côté | E15: 3 × 20 + élastique | F15: Monte lentement, pied légèrement tourné vers le bas.
B16: Donkey kicks | C16: 3 × 15 / côté | D16: 4 × 15 / côté | E16: 4 × 15 + élastique | F16: Dos plat, c'est la fesse qui pousse, pas le dos.
B17: Chaise contre le mur | C17: 3 × 30 s | D17: 3 × 45 s | E17: 3 × 60 s | F17: Cuisses parallèles au sol, respire.
B18: Récup entre les séries | C18: 60 s | D18: 45 s | E18: 45 s
B20: B — Ventre & Gainage · 25 min
B21: Exercice | C21: Phase 1 (S1-2) | D21: Phase 2 (S3-5) | E21: Phase 3 (S6-8) | F21: Le conseil d'Ornella
B22: Dead bug | C22: 3 × 10 / côté | D22: 3 × 12 / côté | E22: 4 × 12 / côté | F22: Bas du dos collé au sol du début à la fin.
B23: Planche sur les avant-bras | C23: 3 × 20 s | D23: 3 × 35 s | E23: 3 × 50 s | F23: Nombril rentré, fessiers serrés, ne creuse pas.
B24: Crunch inversé | C24: 3 × 10 | D24: 3 × 12 | E24: 4 × 15 | F24: Enroule le bassin, ne balance pas les jambes.
B25: Gainage latéral | C25: 3 × 15 s / côté | D25: 3 × 25 s / côté | E25: 3 × 35 s / côté | F25: Genoux au sol si besoin, hanches bien hautes.
B26: Bird dog | C26: 3 × 10 / côté | D26: 3 × 12 / côté | E26: 3 × 12 (pause 2 s) | F26: Bras et jambe opposés, le bassin ne bouge pas.
B27: Mountain climbers lents | C27: 3 × 20 s | D27: 3 × 30 s | E27: 4 × 30 s | F27: Contrôle > vitesse. Expire à chaque genou.
B28: Récup entre les séries | C28: 45 s | D28: 40 s | E28: 30 s
B30: C — Full body brûle-calories (circuit) · 30 min
B31: Exercice | C31: Phase 1 (S1-2) | D31: Phase 2 (S3-5) | E31: Phase 3 (S6-8) | F31: Le conseil d'Ornella
B32: Format du circuit | C32: 3 tours · 40 s effort / 20 s récup | D32: 4 tours · 40 s / 20 s | E32: 5 tours · 45 s / 15 s | F32: 1 min de pause entre chaque tour.
B33: Squat | C33: Squat classique | D33: Squat + pause 1 s en bas | E33: Squat sauté (ou squat rapide) | F33: Poids dans les talons.
B34: Pompes | C34: Sur les genoux | D34: Sur les genoux / pieds (alterner) | E34: Sur les pieds | F34: Corps gainé en planche, coudes à 45°.
B35: Fentes alternées | C35: Fentes marchées lentes | D35: Fentes alternées | E35: Fentes sautées (ou rapides) | F35: Genou arrière frôle le sol.
B36: Burpee sans saut | C36: Sans pompe | D36: Avec pompe genoux | E36: Avec saut | F36: Pose les mains, recule un pied après l'autre si besoin.
B37: Jumping jacks | C37: Step jacks (sans impact) | D37: Jumping jacks | E37: Jumping jacks rapides | F37: Sans impact si post-partum ou voisins 😉
B38: Rowing (élastique ou bouteilles) | C38: Bouteilles d'eau | D38: Élastique / haltères légers | E38: Haltères + pause 1 s | F38: Tire les coudes vers les hanches, serre les omoplates.
B40: D — Fessiers Sculpt · 35 min
B41: Exercice | C41: Phase 1 (S1-2) | D41: Phase 2 (S3-5) | E41: Phase 3 (S6-8) | F41: Le conseil d'Ornella
B42: Soulevé de terre jambes tendues | C42: 3 × 12 | D42: 4 × 12 | E42: 4 × 12 (descente en 3 s) | F42: Haltères, sac à dos ou bidons. Dos plat, on pousse les fesses en arrière.
B43: Squat bulgare (pied arrière sur chaise) | C43: 3 × 8 / jambe | D43: 3 × 10 / jambe | E43: 4 × 10 / jambe | F43: L'exercice n°1 pour les fessiers. Va doucement.
B44: Frog pumps | C44: 3 × 20 | D44: 4 × 20 | E44: 4 × 25 + 10 pulses | F44: Plantes de pieds collées, genoux ouverts.
B45: Montée sur chaise | C45: 3 × 10 / jambe | D45: 3 × 12 / jambe | E45: 4 × 12 / jambe | F45: Pousse dans le talon de la jambe du haut.
B46: Kickback debout (élastique) | C46: 3 × 15 / côté | D46: 3 × 15 / côté | E46: 4 × 15 / côté | F46: Sans élastique : fais-le à 4 pattes.
B47: Pulse squats | C47: 3 × 20 s | D47: 3 × 30 s | E47: 3 × 40 s | F47: Petits mouvements en bas du squat : ça brûle = ça travaille 🔥
...

Sheet Mon suivi
B2: ORNELLA FIT COACHING
B3: Mon suivi
B4: 1 fois par semaine, même jour, le matin à jeun. Le tour de taille est ton meilleur indicateur !
B7: Semaine | C7: Date | D7: Poids (kg) | E7: Tour de taille (cm) | F7: Hanches (cm) | G7: Cuisse (cm) | H7: Énergie /10 | I7: Écart poids | J7: Écart taille
B8: Départ | C8: =IF('Mes calories'!$C$9="","",'Mes calories'!$C$9+0) -> 46300 | I8: =IF(OR(D8="",$D$8=""),"",D8-$D$8) | J8: =IF(OR(E8="",$E$8=""),"",E8-$E$8)
B9: Semaine 1 | C9: =IF('Mes calories'!$C$9="","",'Mes calories'!$C$9+7) -> 46307 | I9: =IF(OR(D9="",$D$8=""),"",D9-$D$8) | J9: =IF(OR(E9="",$E$8=""),"",E9-$E$8)
B10: Semaine 2 | C10: =IF('Mes calories'!$C$9="","",'Mes calories'!$C$9+14) -> 46314 | I10: =IF(OR(D10="",$D$8=""),"",D10-$D$8) | J10: =IF(OR(E10="",$E$8=""),"",E10-$E$8)
B11: Semaine 3 | C11: =IF('Mes calories'!$C$9="","",'Mes calories'!$C$9+21) -> 46321 | I11: =IF(OR(D11="",$D$8=""),"",D11-$D$8) | J11: =IF(OR(E11="",$E$8=""),"",E11-$E$8)
B12: Semaine 4 | C12: =IF('Mes calories'!$C$9="","",'Mes calories'!$C$9+28) -> 46328 | I12: =IF(OR(D12="",$D$8=""),"",D12-$D$8) | J12: =IF(OR(E12="",$E$8=""),"",E12-$E$8)
B13: Semaine 5 | C13: =IF('Mes calories'!$C$9="","",'Mes calories'!$C$9+35) -> 46335 | I13: =IF(OR(D13="",$D$8=""),"",D13-$D$8) | J13: =IF(OR(E13="",$E$8=""),"",E13-$E$8)
B14: Semaine 6 | C14: =IF('Mes calories'!$C$9="","",'Mes calories'!$C$9+42) -> 46342 | I14: =IF(OR(D14="",$D$8=""),"",D14-$D$8) | J14: =IF(OR(E14="",$E$8=""),"",E14-$E$8)
B15: Semaine 7 | C15: =IF('Mes calories'!$C$9="","",'Mes calories'!$C$9+49) -> 46349 | I15: =IF(OR(D15="",$D$8=""),"",D15-$D$8) | J15: =IF(OR(E15="",$E$8=""),"",E15-$E$8)
B16: Semaine 8 | C16: =IF('Mes calories'!$C$9="","",'Mes calories'!$C$9+56) -> 46356 | I16: =IF(OR(D16="",$D$8=""),"",D16-$D$8) | J16: =IF(OR(E16="",$E$8=""),"",E16-$E$8)
B18: 📸 Prends 3 photos (face, profil, dos) au départ, en semaine 4 et en semaine 8. Souvent, les photos montrent le changement avant la balance.

Sheet Repas
B2: ORNELLA FIT COACHING
B3: Repas & ma journée type
B4: Choisis tes repas dans les menus déroulants → le total se compare à ton objectif. Valeurs approximatives.
B7: Moment | C7: Mon choix | E7: kcal | F7: Protéines (g)
B8: Petit-déjeuner | C8: Skyr, avoine & fruits rouges | E8: =IFERROR(INDEX($E$21:$E$45,MATCH(C8,$C$21:$C$45,0)),0) -> 280 | F8: =IFERROR(INDEX($F$21:$F$45,MATCH(C8,$C$21:$C$45,0)),0) -> 22
B9: Déjeuner | C9: Bowl poulet riz | E9: =IFERROR(INDEX($E$21:$E$45,MATCH(C9,$C$21:$C$45,0)),0) -> 545 | F9: =IFERROR(INDEX($F$21:$F$45,MATCH(C9,$C$21:$C$45,0)),0) -> 42
B10: Dîner | C10: Wok de dinde | E10: =IFERROR(INDEX($E$21:$E$45,MATCH(C10,$C$21:$C$45,0)),0) -> 410 | F10: =IFERROR(INDEX($F$21:$F$45,MATCH(C10,$C$21:$C$45,0)),0) -> 40
B11: Collation 1 | C11: Skyr & fruit | E11: =IFERROR(INDEX($E$21:$E$45,MATCH(C11,$C$21:$C$45,0)),0) -> 175 | F11: =IFERROR(INDEX($F$21:$F$45,MATCH(C11,$C$21:$C$45,0)),0) -> 16
B12: Collation 2 | C12: — Aucun — | E12: =IFERROR(INDEX($E$21:$E$45,MATCH(C12,$C$21:$C$45,0)),0) -> 0 | F12: =IFERROR(INDEX($F$21:$F$45,MATCH(C12,$C$21:$C$45,0)),0) -> 0
B13: Total | E13: =SUM(E8:E12) -> 1410 | F13: =SUM(F8:F12) -> 120
B14: Mon objectif | E14: ='Mes calories'!C19 -> 1660 | F14: ='Mes calories'!C20 -> 130
B15: Il me reste | E15: =IF(E14="","",E14-E13) -> 250 | F15: =IF(F14="","",F14-F13) -> 10
B17: Vert = tu es dans ton objectif. Corail = tu dépasses : remplace un repas ou une collation.
B19: Idées de repas
B20: Catégorie | C20: Repas | D20: Quantités | E20: kcal | F20: Protéines (g)
C21: — Aucun — | E21: 0 | F21: 0
B22: Petit-déjeuner | C22: Skyr, avoine & fruits rouges | D22: 150 g skyr + 40 g flocons d'avoine + 80 g fruits rouges | E22: 280 | F22: 22
B23: Petit-déjeuner | C23: Œufs brouillés & avocat | D23: 2 œufs + 1 tranche pain complet + ½ avocat | E23: 370 | F23: 18
B24: Petit-déjeuner | C24: Porridge banane | D24: 40 g avoine + 250 ml lait écrémé + 1 banane | E24: 340 | F24: 15
B25: Petit-déjeuner | C25: Tartines saumon | D25: 2 tranches pain complet + 60 g fromage frais 0 % + 50 g saumon fumé | E25: 320 | F25: 24
B26: Petit-déjeuner | C26: Smoothie protéiné | D26: 250 ml lait d'amande + 1 banane + 30 g whey + 15 g beurre de cacahuète | E26: 345 | F26: 30
B27: Petit-déjeuner | C27: Pancakes 3 ingrédients | D27: 1 œuf + 1 banane + 30 g flocons d'avoine | E27: 285 | F27: 12
B28: Déjeuner | C28: Bowl poulet riz | D28: 120 g poulet cuit + 60 g riz cru + légumes + 1 c. à s. huile d'olive | E28: 545 | F28: 42
B29: Déjeuner | C29: Salade quinoa thon | D29: 50 g quinoa cru + 1 boîte thon naturel + crudités + 1 c. à s. huile | E29: 430 | F29: 34
B30: Déjeuner | C30: Wrap dinde | D30: 1 tortilla complète + 80 g dinde + crudités + 1 c. à s. fromage frais léger | E30: 310 | F30: 25
B31: Déjeuner | C31: Saumon & patate douce | D31: 120 g saumon + 200 g patate douce + 200 g haricots verts | E31: 480 | F31: 31
B32: Déjeuner | C32: Buddha bowl pois chiches | D32: 150 g pois chiches cuits + 50 g quinoa cru + légumes rôtis + 1 c. à s. tahini | E32: 535 | F32: 23
B33: Déjeuner | C33: Omelette légumes | D33: 3 œufs + légumes + 1 tranche pain complet + salade | E33: 350 | F33: 23
... B45: Collation | C45: Fromage blanc gourmand | D45: 150 g fromage blanc 0 % + cannelle + 10 g chocolat noir | E45: 130 | F45: 12

Sheet Aller plus loin
B2: ORNELLA FIT COACHING
B3: Et après ?
B5: ⭐ Tu aimes ton planner ?
B6: Laisse-moi un avis sur Etsy : ça m'aide énormément et ça aide d'autres femmes à se lancer. Merci 💛
B8: 🎯 Tu veux aller plus vite, avec un programme 100 % pour toi ?
B9: Je suis Ornella, coach sportive diplômée d'État. J'accompagne les femmes à distance ou en présentiel (Essonne / Hauts-de-Seine) : programme sur-mesure, nutrition, bilans réguliers et suivi WhatsApp.
B11: 👉 Découvre mes accompagnements
B12: ornellafitcoaching.com
B14: 📲 Suis-moi pour des conseils chaque semaine
B15: TikTok : @coachornella

Sheet Listes
B2: activity | C2: factor | E2: goal | F2: deficit | H2: weight_kg | I2: height_cm | J2: w_unit | K2: h_unit | P2: cat0 | Q2: cat1 | R2: cat2 | S2: cat3
B3: Sédentaire (bureau, peu de marche) | C3: 1.2 | E3: Perte douce (-10 %) | F3: 0.1 | H3: ='Mes calories'!C11 -> 72 | I3: ='Mes calories'!C12 -> 165 | J3: kg | K3: cm | P3: — Aucun — | Q3: — Aucun — | R3: — Aucun — | S3: — Aucun —
B4: Légèrement active (1-3 séances/sem) | C4: 1.375 | E4: Perte régulière (-15 %) | F4: 0.15 | P4: Skyr, avoine & fruits rouges | Q4: Bowl poulet riz | R4: Cabillaud & légumes vapeur | S4: Skyr & fruit
B5: Active (3-5 séances/sem) | C5: 1.55 | E5: Perte active (-20 %) | F5: 0.2 | P5: Œufs brouillés & avocat | Q5: Salade quinoa thon | R5: Wok de dinde | S5: Pomme & beurre de cacahuète
B6: Très active (6-7 séances/sem ou métier physique) | C6: 1.725 | E6: Maintien (0 %) | F6: 0 | P6: Porridge banane | Q6: Wrap dinde | R6: Soupe & œufs durs | S6: Amandes
P7: Tartines saumon | Q7: Saumon & patate douce | R7: Chili con carne | S7: Galettes de riz & houmous
P8: Smoothie protéiné | Q8: Buddha bowl pois chiches | R8: Curry de lentilles corail | S8: Shaker whey
P9: Pancakes 3 ingrédients | Q9: Omelette légumes | R9: Pizza tortilla maison | S9: Fromage blanc gourmand
